Workbook

Sheet Start Here
A1: Smart Budget Planner
A2: Track every dollar · see where your money goes · hit your goals
A4: 1. Go to Settings: set your currency and edit the categories + monthly budget (yellow cells).
A5: 2. Go to Transactions: log each income or expense. Pick Type and Category from the dropdowns.
A6: 3. Open Dashboard: pick a month at the top to see budget vs actual, charts and savings rate.
A7: 4. Savings Goals: add goals; see the % done and how much to save each month.
A8: 5. Debt Payoff: enter each debt; see months to debt-free and total interest.
A9: 6. Bills: list recurring bills and tick each month when paid.
A11: Legend: YELLOW cells = type here. White cells = automatic formulas (don't edit).
A12: Example rows are included so you can see how it works. Delete them and start your own.
A13: Google Sheets: File → Import → Upload → 'Replace spreadsheet'. Excel: just open it.
A15: © Smart Budget Planner · personal use only

Sheet Settings
A1: Settings
A3: Currency symbol | B3: $
A4: Year | B4: 2027
A5: Starting balance | B5: 1000
A7: Category | B7: Type | C7: Monthly Budget | D7: Spent This Year | E7: Avg / Month
A8: Salary | B8: Income | D8: =IF(A8="","",SUMIFS(Transactions!$E:$E,Transactions!$C:$C,A8,Transactions!$B:$B,B8)) -> 3500 | E8: =IF(A8="","",D8/MAX(1,MAX(Transactions!$F:$F))) -> 3500
A9: Side Hustle | B9: Income | D9: =IF(A9="","",SUMIFS(Transactions!$E:$E,Transactions!$C:$C,A9,Transactions!$B:$B,B9)) -> 400 | E9: =IF(A9="","",D9/MAX(1,MAX(Transactions!$F:$F))) -> 400
A10: Gifts / Other | B10: Income | D10: =IF(A10="","",SUMIFS(Transactions!$E:$E,Transactions!$C:$C,A10,Transactions!$B:$B,B10)) -> 0 | E10: =IF(A10="","",D10/MAX(1,MAX(Transactions!$F:$F))) -> 0
A11: Rent / Mortgage | B11: Expense | C11: 1200 | D11: =IF(A11="","",SUMIFS(Transactions!$E:$E,Transactions!$C:$C,A11,Transactions!$B:$B,B11)) -> 1200 | E11: =IF(A11="","",D11/MAX(1,MAX(Transactions!$F:$F))) -> 1200
A12: Groceries | B12: Expense | C12: 450 | D12: =IF(A12="","",SUMIFS(Transactions!$E:$E,Transactions!$C:$C,A12,Transactions!$B:$B,B12)) -> 184.6 | E12: =IF(A12="","",D12/MAX(1,MAX(Transactions!$F:$F))) -> 184.6
A13: Utilities | B13: Expense | C13: 180 | D13: =IF(A13="","",SUMIFS(Transactions!$E:$E,Transactions!$C:$C,A13,Transactions!$B:$B,B13)) -> 74 | E13: =IF(A13="","",D13/MAX(1,MAX(Transactions!$F:$F))) -> 74
A14: Transport | B14: Expense | C14: 200 | D14: =IF(A14="","",SUMIFS(Transactions!$E:$E,Transactions!$C:$C,A14,Transactions!$B:$B,B14)) -> 55 | E14: =IF(A14="","",D14/MAX(1,MAX(Transactions!$F:$F))) -> 55
A15: Phone & Internet | B15: Expense | C15: 80 | D15: =IF(A15="","",SUMIFS(Transactions!$E:$E,Transactions!$C:$C,A15,Transactions!$B:$B,B15)) -> 0 | E15: =IF(A15="","",D15/MAX(1,MAX(Transactions!$F:$F))) -> 0
A16: Eating Out | B16: Expense | C16: 150 | D16: =IF(A16="","",SUMIFS(Transactions!$E:$E,Transactions!$C:$C,A16,Transactions!$B:$B,B16)) -> 32.5 | E16: =IF(A16="","",D16/MAX(1,MAX(Transactions!$F:$F))) -> 32.5
A17: Shopping | B17: Expense | C17: 120 | D17: =IF(A17="","",SUMIFS(Transactions!$E:$E,Transactions!$C:$C,A17,Transactions!$B:$B,B17)) -> 0 | E17: =IF(A17="","",D17/MAX(1,MAX(Transactions!$F:$F))) -> 0
A18: Health | B18: Expense | C18: 60 | D18: =IF(A18="","",SUMIFS(Transactions!$E:$E,Transactions!$C:$C,A18,Transactions!$B:$B,B18)) -> 0 | E18: =IF(A18="","",D18/MAX(1,MAX(Transactions!$F:$F))) -> 0
A19: Kids / Family | B19: Expense | C19: 150 | D19: =IF(A19="","",SUMIFS(Transactions!$E:$E,Transactions!$C:$C,A19,Transactions!$B:$B,B19)) -> 0 | E19: =IF(A19="","",D19/MAX(1,MAX(Transactions!$F:$F))) -> 0
A20: Subscriptions | B20: Expense | C20: 40 | D20: =IF(A20="","",SUMIFS(Transactions!$E:$E,Transactions!$C:$C,A20,Transactions!$B:$B,B20)) -> 15.99 | E20: =IF(A20="","",D20/MAX(1,MAX(Transactions!$F:$F))) -> 15.99
A21: Education | B21: Expense | C21: 50 | D21: =IF(A21="","",SUMIFS(Transactions!$E:$E,Transactions!$C:$C,A21,Transactions!$B:$B,B21)) -> 0 | E21: =IF(A21="","",D21/MAX(1,MAX(Transactions!$F:$F))) -> 0
A22: Charity / Zakat | B22: Expense | C22: 50 | D22: =IF(A22="","",SUMIFS(Transactions!$E:$E,Transactions!$C:$C,A22,Transactions!$B:$B,B22)) -> 0 | E22: =IF(A22="","",D22/MAX(1,MAX(Transactions!$F:$F))) -> 0
... A26: Miscellaneous | B26: Expense | C26: 50 | D26: =IF(A26="","",SUMIFS(Transactions!$E:$E,Transactions!$C:$C,A26,Transactions!$B:$B,B26)) -> 0 | E26: =IF(A26="","",D26/MAX(1,MAX(Transactions!$F:$F))) -> 0
D27: =IF(A27="","",SUMIFS(Transactions!$E:$E,Transactions!$C:$C,A27,Transactions!$B:$B,B27)) | E27: =IF(A27="","",D27/MAX(1,MAX(Transactions!$F:$F)))
D28: =IF(A28="","",SUMIFS(Transactions!$E:$E,Transactions!$C:$C,A28,Transactions!$B:$B,B28)) | E28: =IF(A28="","",D28/MAX(1,MAX(Transactions!$F:$F)))
D29: =IF(A29="","",SUMIFS(Transactions!$E:$E,Transactions!$C:$C,A29,Transactions!$B:$B,B29)) | E29: =IF(A29="","",D29/MAX(1,MAX(Transactions!$F:$F)))
D30: =IF(A30="","",SUMIFS(Transactions!$E:$E,Transactions!$C:$C,A30,Transactions!$B:$B,B30)) | E30: =IF(A30="","",D30/MAX(1,MAX(Transactions!$F:$F)))
D31: =IF(A31="","",SUMIFS(Transactions!$E:$E,Transactions!$C:$C,A31,Transactions!$B:$B,B31)) | E31: =IF(A31="","",D31/MAX(1,MAX(Transactions!$F:$F)))
D32: =IF(A32="","",SUMIFS(Transactions!$E:$E,Transactions!$C:$C,A32,Transactions!$B:$B,B32)) | E32: =IF(A32="","",D32/MAX(1,MAX(Transactions!$F:$F)))
D33: =IF(A33="","",SUMIFS(Transactions!$E:$E,Transactions!$C:$C,A33,Transactions!$B:$B,B33)) | E33: =IF(A33="","",D33/MAX(1,MAX(Transactions!$F:$F)))
D34: =IF(A34="","",SUMIFS(Transactions!$E:$E,Transactions!$C:$C,A34,Transactions!$B:$B,B34)) | E34: =IF(A34="","",D34/MAX(1,MAX(Transactions!$F:$F)))
D35: =IF(A35="","",SUMIFS(Transactions!$E:$E,Transactions!$C:$C,A35,Transactions!$B:$B,B35)) | E35: =IF(A35="","",D35/MAX(1,MAX(Transactions!$F:$F)))
D36: =IF(A36="","",SUMIFS(Transactions!$E:$E,Transactions!$C:$C,A36,Transactions!$B:$B,B36)) | E36: =IF(A36="","",D36/MAX(1,MAX(Transactions!$F:$F)))
D37: =IF(A37="","",SUMIFS(Transactions!$E:$E,Transactions!$C:$C,A37,Transactions!$B:$B,B37)) | E37: =IF(A37="","",D37/MAX(1,MAX(Transactions!$F:$F)))

Sheet Transactions
A1: Transactions
A2: Example rows are included so you can see how it works. Delete them and start your own.
A3: Date | B3: Type | C3: Category | D3: Description | E3: Amount | F3: Month
A4: 46388 | B4: Income | C4: Salary | D4: Monthly salary | E4: 3500 | F4: =IF(A4="","",MONTH(A4)) -> 1
A5: 46389 | B5: Expense | C5: Rent / Mortgage | D5: Rent | E5: 1200 | F5: =IF(A5="","",MONTH(A5)) -> 1
A6: 46390 | B6: Expense | C6: Groceries | D6: Supermarket | E6: 96.4 | F6: =IF(A6="","",MONTH(A6)) -> 1
A7: 46392 | B7: Expense | C7: Transport | D7: Fuel | E7: 55 | F7: =IF(A7="","",MONTH(A7)) -> 1
A8: 46395 | B8: Expense | C8: Eating Out | D8: Pizza night | E8: 32.5 | F8: =IF(A8="","",MONTH(A8)) -> 1
A9: 46399 | B9: Expense | C9: Utilities | D9: Electricity | E9: 74 | F9: =IF(A9="","",MONTH(A9)) -> 1
A10: 46402 | B10: Income | C10: Side Hustle | D10: Freelance project | E10: 400 | F10: =IF(A10="","",MONTH(A10)) -> 1
A11: 46405 | B11: Expense | C11: Subscriptions | D11: Streaming | E11: 15.99 | F11: =IF(A11="","",MONTH(A11)) -> 1
A12: 46407 | B12: Expense | C12: Savings Transfer | D12: Emergency fund | E12: 300 | F12: =IF(A12="","",MONTH(A12)) -> 1
A13: 46411 | B13: Expense | C13: Groceries | D13: Weekly shop | E13: 88.2 | F13: =IF(A13="","",MONTH(A13)) -> 1
F14: =IF(A14="","",MONTH(A14))
F15: =IF(A15="","",MONTH(A15))
F16: =IF(A16="","",MONTH(A16))
F17: =IF(A17="","",MONTH(A17))
F18: =IF(A18="","",MONTH(A18))
F19: =IF(A19="","",MONTH(A19))
F20: =IF(A20="","",MONTH(A20))
F21: =IF(A21="","",MONTH(A21))
F22: =IF(A22="","",MONTH(A22))
F23: =IF(A23="","",MONTH(A23))
F24: =IF(A24="","",MONTH(A24))
F25: =IF(A25="","",MONTH(A25))
... F1003: =IF(A1003="","",MONTH(A1003))

Sheet Dashboard
A1: Dashboard
B3: Choose month → | C3: Jan | D3: =MATCH(C3,$Z$40:$Z$51,0) -> 1
B5: Income | D5: Expenses | F5: Net (saved) | H5: Savings rate
B6: =SUMIFS(Transactions!$E:$E,Transactions!$B:$B,"Income",Transactions!$F:$F,$D$3) -> 3900 | D6: =SUMIFS(Transactions!$E:$E,Transactions!$B:$B,"Expense",Transactions!$F:$F,$D$3) -> 1862.09 | F6: =B6-D6 -> 2037.91 | H6: =IF(B6=0,0,F6/B6) -> 0.52254103
B8: Category | C8: Budget | D8: Actual | E8: Difference | F8: Status | H8: Month | I8: Income | J8: Expenses | K8: Net | L8: Savings rate | M8: Balance
B9: =IF(Settings!$B11="Expense",Settings!$A11,"") -> Rent / Mortgage | C9: =IF(B9="","",Settings!$C11) -> 1200 | D9: =IF(B9="","",SUMIFS(Transactions!$E:$E,Transactions!$C:$C,B9,Transactions!$B:$B,"Expense",Transactions!$F:$F,$D$3)) -> 1200 | E9: =IF(B9="","",C9-D9) -> 0 | F9: =IF(B9="","",IF(D9>C9,"✗ Over budget","✓ On track")) -> ✓ On track | H9: Jan | I9: =SUMIFS(Transactions!$E:$E,Transactions!$B:$B,"Income",Transactions!$F:$F,1) -> 3900 | J9: =SUMIFS(Transactions!$E:$E,Transactions!$B:$B,"Expense",Transactions!$F:$F,1) -> 1862.09 | K9: =I9-J9 -> 2037.91 | L9: =IF(I9=0,0,K9/I9) -> 0.52254103 | M9: =Settings!$B$5+K9 -> 3037.91
B10: =IF(Settings!$B12="Expense",Settings!$A12,"") -> Groceries | C10: =IF(B10="","",Settings!$C12) -> 450 | D10: =IF(B10="","",SUMIFS(Transactions!$E:$E,Transactions!$C:$C,B10,Transactions!$B:$B,"Expense",Transactions!$F:$F,$D$3)) -> 184.6 | E10: =IF(B10="","",C10-D10) -> 265.4 | F10: =IF(B10="","",IF(D10>C10,"✗ Over budget","✓ On track")) -> ✓ On track | H10: Feb | I10: =SUMIFS(Transactions!$E:$E,Transactions!$B:$B,"Income",Transactions!$F:$F,2) -> 0 | J10: =SUMIFS(Transactions!$E:$E,Transactions!$B:$B,"Expense",Transactions!$F:$F,2) -> 0 | K10: =I10-J10 -> 0 | L10: =IF(I10=0,0,K10/I10) -> 0 | M10: =M9+K10 -> 3037.91
B11: =IF(Settings!$B13="Expense",Settings!$A13,"") -> Utilities | C11: =IF(B11="","",Settings!$C13) -> 180 | D11: =IF(B11="","",SUMIFS(Transactions!$E:$E,Transactions!$C:$C,B11,Transactions!$B:$B,"Expense",Transactions!$F:$F,$D$3)) -> 74 | E11: =IF(B11="","",C11-D11) -> 106 | F11: =IF(B11="","",IF(D11>C11,"✗ Over budget","✓ On track")) -> ✓ On track | H11: Mar | I11: =SUMIFS(Transactions!$E:$E,Transactions!$B:$B,"Income",Transactions!$F:$F,3) -> 0 | J11: =SUMIFS(Transactions!$E:$E,Transactions!$B:$B,"Expense",Transactions!$F:$F,3) -> 0 | K11: =I11-J11 -> 0 | L11: =IF(I11=0,0,K11/I11) -> 0 | M11: =M10+K11 -> 3037.91
B12: =IF(Settings!$B14="Expense",Settings!$A14,"") -> Transport | C12: =IF(B12="","",Settings!$C14) -> 200 | D12: =IF(B12="","",SUMIFS(Transactions!$E:$E,Transactions!$C:$C,B12,Transactions!$B:$B,"Expense",Transactions!$F:$F,$D$3)) -> 55 | E12: =IF(B12="","",C12-D12) -> 145 | F12: =IF(B12="","",IF(D12>C12,"✗ Over budget","✓ On track")) -> ✓ On track | H12: Apr | I12: =SUMIFS(Transactions!$E:$E,Transactions!$B:$B,"Income",Transactions!$F:$F,4) -> 0 | J12: =SUMIFS(Transactions!$E:$E,Transactions!$B:$B,"Expense",Transactions!$F:$F,4) -> 0 | K12: =I12-J12 -> 0 | L12: =IF(I12=0,0,K12/I12) -> 0 | M12: =M11+K12 -> 3037.91
B13: =IF(Settings!$B15="Expense",Settings!$A15,"") -> Phone & Internet | C13: =IF(B13="","",Settings!$C15) -> 80 | D13: =IF(B13="","",SUMIFS(Transactions!$E:$E,Transactions!$C:$C,B13,Transactions!$B:$B,"Expense",Transactions!$F:$F,$D$3)) -> 0 | E13: =IF(B13="","",C13-D13) -> 80 | F13: =IF(B13="","",IF(D13>C13,"✗ Over budget","✓ On track")) -> ✓ On track | H13: May | I13: =SUMIFS(Transactions!$E:$E,Transactions!$B:$B,"Income",Transactions!$F:$F,5) -> 0 | J13: =SUMIFS(Transactions!$E:$E,Transactions!$B:$B,"Expense",Transactions!$F:$F,5) -> 0 | K13: =I13-J13 -> 0 | L13: =IF(I13=0,0,K13/I13) -> 0 | M13: =M12+K13 -> 3037.91
B14: =IF(Settings!$B16="Expense",Settings!$A16,"") -> Eating Out | C14: =IF(B14="","",Settings!$C16) -> 150 | D14: =IF(B14="","",SUMIFS(Transactions!$E:$E,Transactions!$C:$C,B14,Transactions!$B:$B,"Expense",Transactions!$F:$F,$D$3)) -> 32.5 | E14: =IF(B14="","",C14-D14) -> 117.5 | F14: =IF(B14="","",IF(D14>C14,"✗ Over budget","✓ On track")) -> ✓ On track | H14: Jun | I14: =SUMIFS(Transactions!$E:$E,Transactions!$B:$B,"Income",Transactions!$F:$F,6) -> 0 | J14: =SUMIFS(Transactions!$E:$E,Transactions!$B:$B,"Expense",Transactions!$F:$F,6) -> 0 | K14: =I14-J14 -> 0 | L14: =IF(I14=0,0,K14/I14) -> 0 | M14: =M13+K14 -> 3037.91
B15: =IF(Settings!$B17="Expense",Settings!$A17,"") -> Shopping | C15: =IF(B15="","",Settings!$C17) -> 120 | D15: =IF(B15="","",SUMIFS(Transactions!$E:$E,Transactions!$C:$C,B15,Transactions!$B:$B,"Expense",Transactions!$F:$F,$D$3)) -> 0 | E15: =IF(B15="","",C15-D15) -> 120 | F15: =IF(B15="","",IF(D15>C15,"✗ Over budget","✓ On track")) -> ✓ On track | H15: Jul | I15: =SUMIFS(Transactions!$E:$E,Transactions!$B:$B,"Income",Transactions!$F:$F,7) -> 0 | J15: =SUMIFS(Transactions!$E:$E,Transactions!$B:$B,"Expense",Transactions!$F:$F,7) -> 0 | K15: =I15-J15 -> 0 | L15: =IF(I15=0,0,K15/I15) -> 0 | M15: =M14+K15 -> 3037.91
B16: =IF(Settings!$B18="Expense",Settings!$A18,"") -> Health | C16: =IF(B16="","",Settings!$C18) -> 60 | D16: =IF(B16="","",SUMIFS(Transactions!$E:$E,Transactions!$C:$C,B16,Transactions!$B:$B,"Expense",Transactions!$F:$F,$D$3)) -> 0 | E16: =IF(B16="","",C16-D16) -> 60 | F16: =IF(B16="","",IF(D16>C16,"✗ Over budget","✓ On track")) -> ✓ On track | H16: Aug | I16: =SUMIFS(Transactions!$E:$E,Transactions!$B:$B,"Income",Transactions!$F:$F,8) -> 0 | J16: =SUMIFS(Transactions!$E:$E,Transactions!$B:$B,"Expense",Transactions!$F:$F,8) -> 0 | K16: =I16-J16 -> 0 | L16: =IF(I16=0,0,K16/I16) -> 0 | M16: =M15+K16 -> 3037.91
B17: =IF(Settings!$B19="Expense",Settings!$A19,"") -> Kids / Family | C17: =IF(B17="","",Settings!$C19) -> 150 | D17: =IF(B17="","",SUMIFS(Transactions!$E:$E,Transactions!$C:$C,B17,Transactions!$B:$B,"Expense",Transactions!$F:$F,$D$3)) -> 0 | E17: =IF(B17="","",C17-D17) -> 150 | F17: =IF(B17="","",IF(D17>C17,"✗ Over budget","✓ On track")) -> ✓ On track | H17: Sep | I17: =SUMIFS(Transactions!$E:$E,Transactions!$B:$B,"Income",Transactions!$F:$F,9) -> 0 | J17: =SUMIFS(Transactions!$E:$E,Transactions!$B:$B,"Expense",Transactions!$F:$F,9) -> 0 | K17: =I17-J17 -> 0 | L17: =IF(I17=0,0,K17/I17) -> 0 | M17: =M16+K17 -> 3037.91
B18: =IF(Settings!$B20="Expense",Settings!$A20,"") -> Subscriptions | C18: =IF(B18="","",Settings!$C20) -> 40 | D18: =IF(B18="","",SUMIFS(Transactions!$E:$E,Transactions!$C:$C,B18,Transactions!$B:$B,"Expense",Transactions!$F:$F,$D$3)) -> 15.99 | E18: =IF(B18="","",C18-D18) -> 24.01 | F18: =IF(B18="","",IF(D18>C18,"✗ Over budget","✓ On track")) -> ✓ On track | H18: Oct | I18: =SUMIFS(Transactions!$E:$E,Transactions!$B:$B,"Income",Transactions!$F:$F,10) -> 0 | J18: =SUMIFS(Transactions!$E:$E,Transactions!$B:$B,"Expense",Transactions!$F:$F,10) -> 0 | K18: =I18-J18 -> 0 | L18: =IF(I18=0,0,K18/I18) -> 0 | M18: =M17+K18 -> 3037.91
B19: =IF(Settings!$B21="Expense",Settings!$A21,"") -> Education | C19: =IF(B19="","",Settings!$C21) -> 50 | D19: =IF(B19="","",SUMIFS(Transactions!$E:$E,Transactions!$C:$C,B19,Transactions!$B:$B,"Expense",Transactions!$F:$F,$D$3)) -> 0 | E19: =IF(B19="","",C19-D19) -> 50 | F19: =IF(B19="","",IF(D19>C19,"✗ Over budget","✓ On track")) -> ✓ On track | H19: Nov | I19: =SUMIFS(Transactions!$E:$E,Transactions!$B:$B,"Income",Transactions!$F:$F,11) -> 0 | J19: =SUMIFS(Transactions!$E:$E,Transactions!$B:$B,"Expense",Transactions!$F:$F,11) -> 0 | K19: =I19-J19 -> 0 | L19: =IF(I19=0,0,K19/I19) -> 0 | M19: =M18+K19 -> 3037.91
B20: =IF(Settings!$B22="Expense",Settings!$A22,"") -> Charity / Zakat | C20: =IF(B20="","",Settings!$C22) -> 50 | D20: =IF(B20="","",SUMIFS(Transactions!$E:$E,Transactions!$C:$C,B20,Transactions!$B:$B,"Expense",Transactions!$F:$F,$D$3)) -> 0 | E20: =IF(B20="","",C20-D20) -> 50 | F20: =IF(B20="","",IF(D20>C20,"✗ Over budget","✓ On track")) -> ✓ On track | H20: Dec | I20: =SUMIFS(Transactions!$E:$E,Transactions!$B:$B,"Income",Transactions!$F:$F,12) -> 0 | J20: =SUMIFS(Transactions!$E:$E,Transactions!$B:$B,"Expense",Transactions!$F:$F,12) -> 0 | K20: =I20-J20 -> 0 | L20: =IF(I20=0,0,K20/I20) -> 0 | M20: =M19+K20 -> 3037.91
B21: =IF(Settings!$B23="Expense",Settings!$A23,"") -> Entertainment | C21: =IF(B21="","",Settings!$C23) -> 60 | D21: =IF(B21="","",SUMIFS(Transactions!$E:$E,Transactions!$C:$C,B21,Transactions!$B:$B,"Expense",Transactions!$F:$F,$D$3)) -> 0 | E21: =IF(B21="","",C21-D21) -> 60 | F21: =IF(B21="","",IF(D21>C21,"✗ Over budget","✓ On track")) -> ✓ On track | H21: Σ | I21: =SUM(I9:I20) -> 3900 | J21: =SUM(J9:J20) -> 1862.09 | K21: =SUM(K9:K20) -> 2037.91 | L21: =IF(I21=0,0,K21/I21) -> 0.52254103
B22: =IF(Settings!$B24="Expense",Settings!$A24,"") -> Savings Transfer | C22: =IF(B22="","",Settings!$C24) -> 300 | D22: =IF(B22="","",SUMIFS(Transactions!$E:$E,Transactions!$C:$C,B22,Transactions!$B:$B,"Expense",Transactions!$F:$F,$D$3)) -> 300 | E22: =IF(B22="","",C22-D22) -> 0 | F22: =IF(B22="","",IF(D22>C22,"✗ Over budget","✓ On track")) -> ✓ On track
B23: =IF(Settings!$B25="Expense",Settings!$A25,"") -> Debt Payments | C23: =IF(B23="","",Settings!$C25) -> 200 | D23: =IF(B23="","",SUMIFS(Transactions!$E:$E,Transactions!$C:$C,B23,Transactions!$B:$B,"Expense",Transactions!$F:$F,$D$3)) -> 0 | E23: =IF(B23="","",C23-D23) -> 200 | F23: =IF(B23="","",IF(D23>C23,"✗ Over budget","✓ On track")) -> ✓ On track
B24: =IF(Settings!$B26="Expense",Settings!$A26,"") -> Miscellaneous | C24: =IF(B24="","",Settings!$C26) -> 50 | D24: =IF(B24="","",SUMIFS(Transactions!$E:$E,Transactions!$C:$C,B24,Transactions!$B:$B,"Expense",Transactions!$F:$F,$D$3)) -> 0 | E24: =IF(B24="","",C24-D24) -> 50 | F24: =IF(B24="","",IF(D24>C24,"✗ Over budget","✓ On track")) -> ✓ On track
B25: =IF(Settings!$B27="Expense",Settings!$A27,"") | C25: =IF(B25="","",Settings!$C27) | D25: =IF(B25="","",SUMIFS(Transactions!$E:$E,Transactions!$C:$C,B25,Transactions!$B:$B,"Expense",Transactions!$F:$F,$D$3)) | E25: =IF(B25="","",C25-D25) | F25: =IF(B25="","",IF(D25>C25,"✗ Over budget","✓ On track"))
B26: =IF(Settings!$B28="Expense",Settings!$A28,"") | C26: =IF(B26="","",Settings!$C28) | D26: =IF(B26="","",SUMIFS(Transactions!$E:$E,Transactions!$C:$C,B26,Transactions!$B:$B,"Expense",Transactions!$F:$F,$D$3)) | E26: =IF(B26="","",C26-D26) | F26: =IF(B26="","",IF(D26>C26,"✗ Over budget","✓ On track"))
B27: =IF(Settings!$B29="Expense",Settings!$A29,"") | C27: =IF(B27="","",Settings!$C29) | D27: =IF(B27="","",SUMIFS(Transactions!$E:$E,Transactions!$C:$C,B27,Transactions!$B:$B,"Expense",Transactions!$F:$F,$D$3)) | E27: =IF(B27="","",C27-D27) | F27: =IF(B27="","",IF(D27>C27,"✗ Over budget","✓ On track"))
B28: =IF(Settings!$B30="Expense",Settings!$A30,"") | C28: =IF(B28="","",Settings!$C30) | D28: =IF(B28="","",SUMIFS(Transactions!$E:$E,Transactions!$C:$C,B28,Transactions!$B:$B,"Expense",Transactions!$F:$F,$D$3)) | E28: =IF(B28="","",C28-D28) | F28: =IF(B28="","",IF(D28>C28,"✗ Over budget","✓ On track"))
B29: =IF(Settings!$B31="Expense",Settings!$A31,"") | C29: =IF(B29="","",Settings!$C31) | D29: =IF(B29="","",SUMIFS(Transactions!$E:$E,Transactions!$C:$C,B29,Transactions!$B:$B,"Expense",Transactions!$F:$F,$D$3)) | E29: =IF(B29="","",C29-D29) | F29: =IF(B29="","",IF(D29>C29,"✗ Over budget","✓ On track"))
B30: =IF(Settings!$B32="Expense",Settings!$A32,"") | C30: =IF(B30="","",Settings!$C32) | D30: =IF(B30="","",SUMIFS(Transactions!$E:$E,Transactions!$C:$C,B30,Transactions!$B:$B,"Expense",Transactions!$F:$F,$D$3)) | E30: =IF(B30="","",C30-D30) | F30: =IF(B30="","",IF(D30>C30,"✗ Over budget","✓ On track"))
B31: =IF(Settings!$B33="Expense",Settings!$A33,"") | C31: =IF(B31="","",Settings!$C33) | D31: =IF(B31="","",SUMIFS(Transactions!$E:$E,Transactions!$C:$C,B31,Transactions!$B:$B,"Expense",Transactions!$F:$F,$D$3)) | E31: =IF(B31="","",C31-D31) | F31: =IF(B31="","",IF(D31>C31,"✗ Over budget","✓ On track"))
B32: =IF(Settings!$B34="Expense",Settings!$A34,"") | C32: =IF(B32="","",Settings!$C34) | D32: =IF(B32="","",SUMIFS(Transactions!$E:$E,Transactions!$C:$C,B32,Transactions!$B:$B,"Expense",Transactions!$F:$F,$D$3)) | E32: =IF(B32="","",C32-D32) | F32: =IF(B32="","",IF(D32>C32,"✗ Over budget","✓ On track"))
B33: =IF(Settings!$B35="Expense",Settings!$A35,"") | C33: =IF(B33="","",Settings!$C35) | D33: =IF(B33="","",SUMIFS(Transactions!$E:$E,Transactions!$C:$C,B33,Transactions!$B:$B,"Expense",Transactions!$F:$F,$D$3)) | E33: =IF(B33="","",C33-D33) | F33: =IF(B33="","",IF(D33>C33,"✗ Over budget","✓ On track"))
... B35: =IF(Settings!$B37="Expense",Settings!$A37,"") | C35: =IF(B35="","",Settings!$C37) | D35: =IF(B35="","",SUMIFS(Transactions!$E:$E,Transactions!$C:$C,B35,Transactions!$B:$B,"Expense",Transactions!$F:$F,$D$3)) | E35: =IF(B35="","",C35-D35) | F35: =IF(B35="","",IF(D35>C35,"✗ Over budget","✓ On track"))
Z40: Jan
Z41: Feb
Z42: Mar
Z43: Apr
Z44: May
Z45: Jun
Z46: Jul
Z47: Aug
Z48: Sep
...

Sheet Savings Goals
A1: Savings Goals
A3: Goal | B3: Target | C3: Saved so far | D3: Progress | E3: Remaining | F3: Target date | G3: Save / month
A4: Emergency fund | B4: 6000 | C4: 1500 | D4: =IF(B4="","",MIN(1,C4/B4)) -> 0.25 | E4: =IF(B4="","",MAX(0,B4-C4)) -> 4500 | F4: 46749 | G4: =IF(OR(B4="",F4=""),"",E4/MAX(1,ROUNDUP((F4-TODAY())/30.4,0))) -> 300
A5: Holiday | B5: 2000 | C5: 400 | D5: =IF(B5="","",MIN(1,C5/B5)) -> 0.2 | E5: =IF(B5="","",MAX(0,B5-C5)) -> 1600 | F5: 46627 | G5: =IF(OR(B5="",F5=""),"",E5/MAX(1,ROUNDUP((F5-TODAY())/30.4,0))) -> 145.45455
A6: New laptop | B6: 1200 | C6: 300 | D6: =IF(B6="","",MIN(1,C6/B6)) -> 0.25 | E6: =IF(B6="","",MAX(0,B6-C6)) -> 900 | F6: 46535 | G6: =IF(OR(B6="",F6=""),"",E6/MAX(1,ROUNDUP((F6-TODAY())/30.4,0))) -> 112.5
D7: =IF(B7="","",MIN(1,C7/B7)) | E7: =IF(B7="","",MAX(0,B7-C7)) | G7: =IF(OR(B7="",F7=""),"",E7/MAX(1,ROUNDUP((F7-TODAY())/30.4,0)))
D8: =IF(B8="","",MIN(1,C8/B8)) | E8: =IF(B8="","",MAX(0,B8-C8)) | G8: =IF(OR(B8="",F8=""),"",E8/MAX(1,ROUNDUP((F8-TODAY())/30.4,0)))
D9: =IF(B9="","",MIN(1,C9/B9)) | E9: =IF(B9="","",MAX(0,B9-C9)) | G9: =IF(OR(B9="",F9=""),"",E9/MAX(1,ROUNDUP((F9-TODAY())/30.4,0)))
D10: =IF(B10="","",MIN(1,C10/B10)) | E10: =IF(B10="","",MAX(0,B10-C10)) | G10: =IF(OR(B10="",F10=""),"",E10/MAX(1,ROUNDUP((F10-TODAY())/30.4,0)))
D11: =IF(B11="","",MIN(1,C11/B11)) | E11: =IF(B11="","",MAX(0,B11-C11)) | G11: =IF(OR(B11="",F11=""),"",E11/MAX(1,ROUNDUP((F11-TODAY())/30.4,0)))
D12: =IF(B12="","",MIN(1,C12/B12)) | E12: =IF(B12="","",MAX(0,B12-C12)) | G12: =IF(OR(B12="",F12=""),"",E12/MAX(1,ROUNDUP((F12-TODAY())/30.4,0)))
D13: =IF(B13="","",MIN(1,C13/B13)) | E13: =IF(B13="","",MAX(0,B13-C13)) | G13: =IF(OR(B13="",F13=""),"",E13/MAX(1,ROUNDUP((F13-TODAY())/30.4,0)))
D14: =IF(B14="","",MIN(1,C14/B14)) | E14: =IF(B14="","",MAX(0,B14-C14)) | G14: =IF(OR(B14="",F14=""),"",E14/MAX(1,ROUNDUP((F14-TODAY())/30.4,0)))
D15: =IF(B15="","",MIN(1,C15/B15)) | E15: =IF(B15="","",MAX(0,B15-C15)) | G15: =IF(OR(B15="",F15=""),"",E15/MAX(1,ROUNDUP((F15-TODAY())/30.4,0)))
D16: =IF(B16="","",MIN(1,C16/B16)) | E16: =IF(B16="","",MAX(0,B16-C16)) | G16: =IF(OR(B16="",F16=""),"",E16/MAX(1,ROUNDUP((F16-TODAY())/30.4,0)))
D17: =IF(B17="","",MIN(1,C17/B17)) | E17: =IF(B17="","",MAX(0,B17-C17)) | G17: =IF(OR(B17="",F17=""),"",E17/MAX(1,ROUNDUP((F17-TODAY())/30.4,0)))
D18: =IF(B18="","",MIN(1,C18/B18)) | E18: =IF(B18="","",MAX(0,B18-C18)) | G18: =IF(OR(B18="",F18=""),"",E18/MAX(1,ROUNDUP((F18-TODAY())/30.4,0)))

Sheet Debt Payoff
A1: Debt Payoff
A2: Tip (snowball): pay minimums on all, put every extra dollar on the smallest balance first.
A3: Debt | B3: Balance | C3: Interest % / yr | D3: Monthly payment | E3: Months to pay off | F3: Debt-free by | G3: Total interest
A4: Credit card | B4: 2500 | C4: 0.22 | D4: 150 | E4: =IF(OR(B4="",D4=""),"",IFERROR(ROUNDUP(IF(C4=0,B4/D4,NPER(C4/12,-D4,B4)),0),"∞")) -> 21 | F4: =IF(ISNUMBER(E4),EDATE(TODAY(),E4),"") -> 46943 | G4: =IF(ISNUMBER(E4),MAX(0,E4*D4-B4),"") -> 650
A5: Car loan | B5: 9000 | C5: 0.07 | D5: 250 | E5: =IF(OR(B5="",D5=""),"",IFERROR(ROUNDUP(IF(C5=0,B5/D5,NPER(C5/12,-D5,B5)),0),"∞")) -> 41 | F5: =IF(ISNUMBER(E5),EDATE(TODAY(),E5),"") -> 47551 | G5: =IF(ISNUMBER(E5),MAX(0,E5*D5-B5),"") -> 1250
E6: =IF(OR(B6="",D6=""),"",IFERROR(ROUNDUP(IF(C6=0,B6/D6,NPER(C6/12,-D6,B6)),0),"∞")) | F6: =IF(ISNUMBER(E6),EDATE(TODAY(),E6),"") | G6: =IF(ISNUMBER(E6),MAX(0,E6*D6-B6),"")
E7: =IF(OR(B7="",D7=""),"",IFERROR(ROUNDUP(IF(C7=0,B7/D7,NPER(C7/12,-D7,B7)),0),"∞")) | F7: =IF(ISNUMBER(E7),EDATE(TODAY(),E7),"") | G7: =IF(ISNUMBER(E7),MAX(0,E7*D7-B7),"")
E8: =IF(OR(B8="",D8=""),"",IFERROR(ROUNDUP(IF(C8=0,B8/D8,NPER(C8/12,-D8,B8)),0),"∞")) | F8: =IF(ISNUMBER(E8),EDATE(TODAY(),E8),"") | G8: =IF(ISNUMBER(E8),MAX(0,E8*D8-B8),"")
E9: =IF(OR(B9="",D9=""),"",IFERROR(ROUNDUP(IF(C9=0,B9/D9,NPER(C9/12,-D9,B9)),0),"∞")) | F9: =IF(ISNUMBER(E9),EDATE(TODAY(),E9),"") | G9: =IF(ISNUMBER(E9),MAX(0,E9*D9-B9),"")
E10: =IF(OR(B10="",D10=""),"",IFERROR(ROUNDUP(IF(C10=0,B10/D10,NPER(C10/12,-D10,B10)),0),"∞")) | F10: =IF(ISNUMBER(E10),EDATE(TODAY(),E10),"") | G10: =IF(ISNUMBER(E10),MAX(0,E10*D10-B10),"")
E11: =IF(OR(B11="",D11=""),"",IFERROR(ROUNDUP(IF(C11=0,B11/D11,NPER(C11/12,-D11,B11)),0),"∞")) | F11: =IF(ISNUMBER(E11),EDATE(TODAY(),E11),"") | G11: =IF(ISNUMBER(E11),MAX(0,E11*D11-B11),"")
E12: =IF(OR(B12="",D12=""),"",IFERROR(ROUNDUP(IF(C12=0,B12/D12,NPER(C12/12,-D12,B12)),0),"∞")) | F12: =IF(ISNUMBER(E12),EDATE(TODAY(),E12),"") | G12: =IF(ISNUMBER(E12),MAX(0,E12*D12-B12),"")
E13: =IF(OR(B13="",D13=""),"",IFERROR(ROUNDUP(IF(C13=0,B13/D13,NPER(C13/12,-D13,B13)),0),"∞")) | F13: =IF(ISNUMBER(E13),EDATE(TODAY(),E13),"") | G13: =IF(ISNUMBER(E13),MAX(0,E13*D13-B13),"")
A15: Σ | B15: =SUM(B4:B13) -> 11500 | D15: =SUM(D4:D13) -> 400 | G15: =SUM(G4:G13) -> 1900

Sheet Bills
A1: Bills
A3: Bill | B3: Due day | C3: Amount | D3: Jan | E3: Feb | F3: Mar | G3: Apr | H3: May | I3: Jun | J3: Jul | K3: Aug | L3: Sep | M3: Oct | N3: Nov | O3: Dec
A4: Rent | B4: 1 | C4: 1200
A5: Electricity | B5: 10 | C5: 75
A6: Internet | B6: 15 | C6: 45
A7: Phone | B7: 20 | C7: 35
A30: Σ | C30: =SUM(C4:C28) -> 1355
